Workbook

Sheet Market Input
A1: GEOGRAPHIC EXPANSION — MARKET INPUT
A2: Yellow cells = user input | Gray cells = dropdown selection | White cells = auto-calculated
A4: Market ID | B4: Region | C4: State | D4: City/County Name | E4: Population | F4: Median HH Income | G4: Community Type | H4: Economy Type | I4: City Size | J4: Existing FM Count | K4: Existing FT Count | L4: Farm Count (County) | M4: Growing Season (Days) | N4: University Enrollment | O4: Competition Level | P4: Local Champion | Q4: FT Regulatory Climate | R4: Tourism Level
A5: M-001 | I5: =IF(E5="","",IF(E5<25000,"Micro",IF(E5<100000,"Small",IF(E5<250000,"Medium",IF(E5<1000000,"Large","Metro")))))
A6: M-002 | I6: =IF(E6="","",IF(E6<25000,"Micro",IF(E6<100000,"Small",IF(E6<250000,"Medium",IF(E6<1000000,"Large","Metro")))))
A7: M-003 | I7: =IF(E7="","",IF(E7<25000,"Micro",IF(E7<100000,"Small",IF(E7<250000,"Medium",IF(E7<1000000,"Large","Metro")))))
A8: M-004 | I8: =IF(E8="","",IF(E8<25000,"Micro",IF(E8<100000,"Small",IF(E8<250000,"Medium",IF(E8<1000000,"Large","Metro")))))
A9: M-005 | I9: =IF(E9="","",IF(E9<25000,"Micro",IF(E9<100000,"Small",IF(E9<250000,"Medium",IF(E9<1000000,"Large","Metro")))))
A10: M-006 | I10: =IF(E10="","",IF(E10<25000,"Micro",IF(E10<100000,"Small",IF(E10<250000,"Medium",IF(E10<1000000,"Large","Metro")))))
A11: M-007 | I11: =IF(E11="","",IF(E11<25000,"Micro",IF(E11<100000,"Small",IF(E11<250000,"Medium",IF(E11<1000000,"Large","Metro")))))
A12: M-008 | I12: =IF(E12="","",IF(E12<25000,"Micro",IF(E12<100000,"Small",IF(E12<250000,"Medium",IF(E12<1000000,"Large","Metro")))))
A13: M-009 | I13: =IF(E13="","",IF(E13<25000,"Micro",IF(E13<100000,"Small",IF(E13<250000,"Medium",IF(E13<1000000,"Large","Metro")))))
A14: M-010 | I14: =IF(E14="","",IF(E14<25000,"Micro",IF(E14<100000,"Small",IF(E14<250000,"Medium",IF(E14<1000000,"Large","Metro")))))
A15: M-011 | I15: =IF(E15="","",IF(E15<25000,"Micro",IF(E15<100000,"Small",IF(E15<250000,"Medium",IF(E15<1000000,"Large","Metro")))))
A16: M-012 | I16: =IF(E16="","",IF(E16<25000,"Micro",IF(E16<100000,"Small",IF(E16<250000,"Medium",IF(E16<1000000,"Large","Metro")))))
... A24: M-020 | I24: =IF(E24="","",IF(E24<25000,"Micro",IF(E24<100000,"Small",IF(E24<250000,"Medium",IF(E24<1000000,"Large","Metro")))))

Sheet Scoring Engine
A1: MARKET SCORING ENGINE — All values auto-calculated from Market Input tab
A2: Scores range 0-100. Higher = more attractive market. FM and FT scored independently.
A4: Market ID | B4: City/County | C4: Pop Score | D4: Income Score | E4: FM Density Score | F4: Farm Density Score | G4: Season Score | H4: Community Fit | I4: Economy Score | J4: Tourism Score | K4: Competition | L4: Champion Bonus | M4: FM TOTAL SCORE | N4: FM Grade
A5: ='Market Input'!A5 | B5: ='Market Input'!D5 | C5: =IF('Market Input'!E5="",0,IF('Market Input'!E5<25000,5,IF('Market Input'!E5<100000,15,IF('Market Input'!E5<250000,30,IF('Market Input'!E5<1000000,50,40))))) | D5: =IF('Market Input'!F5="",0,IF('Market Input'!F5<40000,5,IF('Market Input'!F5<60000,20,IF('Market Input'!F5<80000,40,IF('Market Input'!F5<100000,60,50))))) | E5: =IF(OR('Market Input'!J5="",'Market Input'!E5="",'Market Input'!E5=0),0,LET(density,'Market Input'!J5/'Market Input'!E5*100000,IF(density<2,10,IF(density<5,30,IF(density<8,40,20))))) | F5: =IF('Market Input'!L5="",0,IF('Market Input'!L5<100,5,IF('Market Input'!L5<500,20,IF('Market Input'!L5<1000,35,40)))) | G5: =IF('Market Input'!M5="",0,IF('Market Input'!M5<120,10,IF('Market Input'!M5<180,25,IF('Market Input'!M5<240,35,40)))) | H5: =IF('Market Input'!G5="",0,IF('Market Input'!G5="Rural",35,IF('Market Input'!G5="Suburban",35,IF('Market Input'!G5="Urban",25,30)))) | I5: =IF('Market Input'!H5="",0,IF('Market Input'!H5="Agricultural",40,IF('Market Input'!H5="Mixed",30,IF('Market Input'!H5="Tourism",30,IF('Market Input'!H5="Service",25,IF('Market Input'!H5="Technical",20,15)))))) | J5: =IF('Market Input'!R5="",0,IF('Market Input'!R5="None",0,IF('Market Input'!R5="Low",10,IF('Market Input'!R5="Moderate",25,IF('Market Input'!R5="High",35,40))))) | K5: =IF('Market Input'!O5="",0,IF('Market Input'!O5="None",40,IF('Market Input'!O5="Weak",30,IF('Market Input'!O5="Moderate",15,5)))) | L5: =IF('Market Input'!P5="",0,IF('Market Input'!P5="None",5,IF('Market Input'!P5="Contact Only",15,IF('Market Input'!P5="Active Advocate",30,40)))) | M5: =IF('Market Input'!D5="","",ROUND((C5*0.15+D5*0.15+E5*0.15+F5*0.15+G5*0.10+H5*0.10+I5*0.05+J5*0.05+K5*0.05+L5*0.05)/40*100,0)) | N5: =IF(M5="","",IF(M5>=80,"A",IF(M5>=65,"B",IF(M5>=50,"C",IF(M5>=35,"D","F")))))
A6: ='Market Input'!A6 | B6: ='Market Input'!D6 | C6: =IF('Market Input'!E6="",0,IF('Market Input'!E6<25000,5,IF('Market Input'!E6<100000,15,IF('Market Input'!E6<250000,30,IF('Market Input'!E6<1000000,50,40))))) | D6: =IF('Market Input'!F6="",0,IF('Market Input'!F6<40000,5,IF('Market Input'!F6<60000,20,IF('Market Input'!F6<80000,40,IF('Market Input'!F6<100000,60,50))))) | E6: =IF(OR('Market Input'!J6="",'Market Input'!E6="",'Market Input'!E6=0),0,LET(density,'Market Input'!J6/'Market Input'!E6*100000,IF(density<2,10,IF(density<5,30,IF(density<8,40,20))))) | F6: =IF('Market Input'!L6="",0,IF('Market Input'!L6<100,5,IF('Market Input'!L6<500,20,IF('Market Input'!L6<1000,35,40)))) | G6: =IF('Market Input'!M6="",0,IF('Market Input'!M6<120,10,IF('Market Input'!M6<180,25,IF('Market Input'!M6<240,35,40)))) | H6: =IF('Market Input'!G6="",0,IF('Market Input'!G6="Rural",35,IF('Market Input'!G6="Suburban",35,IF('Market Input'!G6="Urban",25,30)))) | I6: =IF('Market Input'!H6="",0,IF('Market Input'!H6="Agricultural",40,IF('Market Input'!H6="Mixed",30,IF('Market Input'!H6="Tourism",30,IF('Market Input'!H6="Service",25,IF('Market Input'!H6="Technical",20,15)))))) | J6: =IF('Market Input'!R6="",0,IF('Market Input'!R6="None",0,IF('Market Input'!R6="Low",10,IF('Market Input'!R6="Moderate",25,IF('Market Input'!R6="High",35,40))))) | K6: =IF('Market Input'!O6="",0,IF('Market Input'!O6="None",40,IF('Market Input'!O6="Weak",30,IF('Market Input'!O6="Moderate",15,5)))) | L6: =IF('Market Input'!P6="",0,IF('Market Input'!P6="None",5,IF('Market Input'!P6="Contact Only",15,IF('Market Input'!P6="Active Advocate",30,40)))) | M6: =IF('Market Input'!D6="","",ROUND((C6*0.15+D6*0.15+E6*0.15+F6*0.15+G6*0.10+H6*0.10+I6*0.05+J6*0.05+K6*0.05+L6*0.05)/40*100,0)) | N6: =IF(M6="","",IF(M6>=80,"A",IF(M6>=65,"B",IF(M6>=50,"C",IF(M6>=35,"D","F")))))
A7: ='Market Input'!A7 | B7: ='Market Input'!D7 | C7: =IF('Market Input'!E7="",0,IF('Market Input'!E7<25000,5,IF('Market Input'!E7<100000,15,IF('Market Input'!E7<250000,30,IF('Market Input'!E7<1000000,50,40))))) | D7: =IF('Market Input'!F7="",0,IF('Market Input'!F7<40000,5,IF('Market Input'!F7<60000,20,IF('Market Input'!F7<80000,40,IF('Market Input'!F7<100000,60,50))))) | E7: =IF(OR('Market Input'!J7="",'Market Input'!E7="",'Market Input'!E7=0),0,LET(density,'Market Input'!J7/'Market Input'!E7*100000,IF(density<2,10,IF(density<5,30,IF(density<8,40,20))))) | F7: =IF('Market Input'!L7="",0,IF('Market Input'!L7<100,5,IF('Market Input'!L7<500,20,IF('Market Input'!L7<1000,35,40)))) | G7: =IF('Market Input'!M7="",0,IF('Market Input'!M7<120,10,IF('Market Input'!M7<180,25,IF('Market Input'!M7<240,35,40)))) | H7: =IF('Market Input'!G7="",0,IF('Market Input'!G7="Rural",35,IF('Market Input'!G7="Suburban",35,IF('Market Input'!G7="Urban",25,30)))) | I7: =IF('Market Input'!H7="",0,IF('Market Input'!H7="Agricultural",40,IF('Market Input'!H7="Mixed",30,IF('Market Input'!H7="Tourism",30,IF('Market Input'!H7="Service",25,IF('Market Input'!H7="Technical",20,15)))))) | J7: =IF('Market Input'!R7="",0,IF('Market Input'!R7="None",0,IF('Market Input'!R7="Low",10,IF('Market Input'!R7="Moderate",25,IF('Market Input'!R7="High",35,40))))) | K7: =IF('Market Input'!O7="",0,IF('Market Input'!O7="None",40,IF('Market Input'!O7="Weak",30,IF('Market Input'!O7="Moderate",15,5)))) | L7: =IF('Market Input'!P7="",0,IF('Market Input'!P7="None",5,IF('Market Input'!P7="Contact Only",15,IF('Market Input'!P7="Active Advocate",30,40)))) | M7: =IF('Market Input'!D7="","",ROUND((C7*0.15+D7*0.15+E7*0.15+F7*0.15+G7*0.10+H7*0.10+I7*0.05+J7*0.05+K7*0.05+L7*0.05)/40*100,0)) | N7: =IF(M7="","",IF(M7>=80,"A",IF(M7>=65,"B",IF(M7>=50,"C",IF(M7>=35,"D","F")))))
A8: ='Market Input'!A8 | B8: ='Market Input'!D8 | C8: =IF('Market Input'!E8="",0,IF('Market Input'!E8<25000,5,IF('Market Input'!E8<100000,15,IF('Market Input'!E8<250000,30,IF('Market Input'!E8<1000000,50,40))))) | D8: =IF('Market Input'!F8="",0,IF('Market Input'!F8<40000,5,IF('Market Input'!F8<60000,20,IF('Market Input'!F8<80000,40,IF('Market Input'!F8<100000,60,50))))) | E8: =IF(OR('Market Input'!J8="",'Market Input'!E8="",'Market Input'!E8=0),0,LET(density,'Market Input'!J8/'Market Input'!E8*100000,IF(density<2,10,IF(density<5,30,IF(density<8,40,20))))) | F8: =IF('Market Input'!L8="",0,IF('Market Input'!L8<100,5,IF('Market Input'!L8<500,20,IF('Market Input'!L8<1000,35,40)))) | G8: =IF('Market Input'!M8="",0,IF('Market Input'!M8<120,10,IF('Market Input'!M8<180,25,IF('Market Input'!M8<240,35,40)))) | H8: =IF('Market Input'!G8="",0,IF('Market Input'!G8="Rural",35,IF('Market Input'!G8="Suburban",35,IF('Market Input'!G8="Urban",25,30)))) | I8: =IF('Market Input'!H8="",0,IF('Market Input'!H8="Agricultural",40,IF('Market Input'!H8="Mixed",30,IF('Market Input'!H8="Tourism",30,IF('Market Input'!H8="Service",25,IF('Market Input'!H8="Technical",20,15)))))) | J8: =IF('Market Input'!R8="",0,IF('Market Input'!R8="None",0,IF('Market Input'!R8="Low",10,IF('Market Input'!R8="Moderate",25,IF('Market Input'!R8="High",35,40))))) | K8: =IF('Market Input'!O8="",0,IF('Market Input'!O8="None",40,IF('Market Input'!O8="Weak",30,IF('Market Input'!O8="Moderate",15,5)))) | L8: =IF('Market Input'!P8="",0,IF('Market Input'!P8="None",5,IF('Market Input'!P8="Contact Only",15,IF('Market Input'!P8="Active Advocate",30,40)))) | M8: =IF('Market Input'!D8="","",ROUND((C8*0.15+D8*0.15+E8*0.15+F8*0.15+G8*0.10+H8*0.10+I8*0.05+J8*0.05+K8*0.05+L8*0.05)/40*100,0)) | N8: =IF(M8="","",IF(M8>=80,"A",IF(M8>=65,"B",IF(M8>=50,"C",IF(M8>=35,"D","F")))))
A9: ='Market Input'!A9 | B9: ='Market Input'!D9 | C9: =IF('Market Input'!E9="",0,IF('Market Input'!E9<25000,5,IF('Market Input'!E9<100000,15,IF('Market Input'!E9<250000,30,IF('Market Input'!E9<1000000,50,40))))) | D9: =IF('Market Input'!F9="",0,IF('Market Input'!F9<40000,5,IF('Market Input'!F9<60000,20,IF('Market Input'!F9<80000,40,IF('Market Input'!F9<100000,60,50))))) | E9: =IF(OR('Market Input'!J9="",'Market Input'!E9="",'Market Input'!E9=0),0,LET(density,'Market Input'!J9/'Market Input'!E9*100000,IF(density<2,10,IF(density<5,30,IF(density<8,40,20))))) | F9: =IF('Market Input'!L9="",0,IF('Market Input'!L9<100,5,IF('Market Input'!L9<500,20,IF('Market Input'!L9<1000,35,40)))) | G9: =IF('Market Input'!M9="",0,IF('Market Input'!M9<120,10,IF('Market Input'!M9<180,25,IF('Market Input'!M9<240,35,40)))) | H9: =IF('Market Input'!G9="",0,IF('Market Input'!G9="Rural",35,IF('Market Input'!G9="Suburban",35,IF('Market Input'!G9="Urban",25,30)))) | I9: =IF('Market Input'!H9="",0,IF('Market Input'!H9="Agricultural",40,IF('Market Input'!H9="Mixed",30,IF('Market Input'!H9="Tourism",30,IF('Market Input'!H9="Service",25,IF('Market Input'!H9="Technical",20,15)))))) | J9: =IF('Market Input'!R9="",0,IF('Market Input'!R9="None",0,IF('Market Input'!R9="Low",10,IF('Market Input'!R9="Moderate",25,IF('Market Input'!R9="High",35,40))))) | K9: =IF('Market Input'!O9="",0,IF('Market Input'!O9="None",40,IF('Market Input'!O9="Weak",30,IF('Market Input'!O9="Moderate",15,5)))) | L9: =IF('Market Input'!P9="",0,IF('Market Input'!P9="None",5,IF('Market Input'!P9="Contact Only",15,IF('Market Input'!P9="Active Advocate",30,40)))) | M9: =IF('Market Input'!D9="","",ROUND((C9*0.15+D9*0.15+E9*0.15+F9*0.15+G9*0.10+H9*0.10+I9*0.05+J9*0.05+K9*0.05+L9*0.05)/40*100,0)) | N9: =IF(M9="","",IF(M9>=80,"A",IF(M9>=65,"B",IF(M9>=50,"C",IF(M9>=35,"D","F")))))
A10: ='Market Input'!A10 | B10: ='Market Input'!D10 | C10: =IF('Market Input'!E10="",0,IF('Market Input'!E10<25000,5,IF('Market Input'!E10<100000,15,IF('Market Input'!E10<250000,30,IF('Market Input'!E10<1000000,50,40))))) | D10: =IF('Market Input'!F10="",0,IF('Market Input'!F10<40000,5,IF('Market Input'!F10<60000,20,IF('Market Input'!F10<80000,40,IF('Market Input'!F10<100000,60,50))))) | E10: =IF(OR('Market Input'!J10="",'Market Input'!E10="",'Market Input'!E10=0),0,LET(density,'Market Input'!J10/'Market Input'!E10*100000,IF(density<2,10,IF(density<5,30,IF(density<8,40,20))))) | F10: =IF('Market Input'!L10="",0,IF('Market Input'!L10<100,5,IF('Market Input'!L10<500,20,IF('Market Input'!L10<1000,35,40)))) | G10: =IF('Market Input'!M10="",0,IF('Market Input'!M10<120,10,IF('Market Input'!M10<180,25,IF('Market Input'!M10<240,35,40)))) | H10: =IF('Market Input'!G10="",0,IF('Market Input'!G10="Rural",35,IF('Market Input'!G10="Suburban",35,IF('Market Input'!G10="Urban",25,30)))) | I10: =IF('Market Input'!H10="",0,IF('Market Input'!H10="Agricultural",40,IF('Market Input'!H10="Mixed",30,IF('Market Input'!H10="Tourism",30,IF('Market Input'!H10="Service",25,IF('Market Input'!H10="Technical",20,15)))))) | J10: =IF('Market Input'!R10="",0,IF('Market Input'!R10="None",0,IF('Market Input'!R10="Low",10,IF('Market Input'!R10="Moderate",25,IF('Market Input'!R10="High",35,40))))) | K10: =IF('Market Input'!O10="",0,IF('Market Input'!O10="None",40,IF('Market Input'!O10="Weak",30,IF('Market Input'!O10="Moderate",15,5)))) | L10: =IF('Market Input'!P10="",0,IF('Market Input'!P10="None",5,IF('Market Input'!P10="Contact Only",15,IF('Market Input'!P10="Active Advocate",30,40)))) | M10: =IF('Market Input'!D10="","",ROUND((C10*0.15+D10*0.15+E10*0.15+F10*0.15+G10*0.10+H10*0.10+I10*0.05+J10*0.05+K10*0.05+L10*0.05)/40*100,0)) | N10: =IF(M10="","",IF(M10>=80,"A",IF(M10>=65,"B",IF(M10>=50,"C",IF(M10>=35,"D","F")))))
A11: ='Market Input'!A11 | B11: ='Market Input'!D11 | C11: =IF('Market Input'!E11="",0,IF('Market Input'!E11<25000,5,IF('Market Input'!E11<100000,15,IF('Market Input'!E11<250000,30,IF('Market Input'!E11<1000000,50,40))))) | D11: =IF('Market Input'!F11="",0,IF('Market Input'!F11<40000,5,IF('Market Input'!F11<60000,20,IF('Market Input'!F11<80000,40,IF('Market Input'!F11<100000,60,50))))) | E11: =IF(OR('Market Input'!J11="",'Market Input'!E11="",'Market Input'!E11=0),0,LET(density,'Market Input'!J11/'Market Input'!E11*100000,IF(density<2,10,IF(density<5,30,IF(density<8,40,20))))) | F11: =IF('Market Input'!L11="",0,IF('Market Input'!L11<100,5,IF('Market Input'!L11<500,20,IF('Market Input'!L11<1000,35,40)))) | G11: =IF('Market Input'!M11="",0,IF('Market Input'!M11<120,10,IF('Market Input'!M11<180,25,IF('Market Input'!M11<240,35,40)))) | H11: =IF('Market Input'!G11="",0,IF('Market Input'!G11="Rural",35,IF('Market Input'!G11="Suburban",35,IF('Market Input'!G11="Urban",25,30)))) | I11: =IF('Market Input'!H11="",0,IF('Market Input'!H11="Agricultural",40,IF('Market Input'!H11="Mixed",30,IF('Market Input'!H11="Tourism",30,IF('Market Input'!H11="Service",25,IF('Market Input'!H11="Technical",20,15)))))) | J11: =IF('Market Input'!R11="",0,IF('Market Input'!R11="None",0,IF('Market Input'!R11="Low",10,IF('Market Input'!R11="Moderate",25,IF('Market Input'!R11="High",35,40))))) | K11: =IF('Market Input'!O11="",0,IF('Market Input'!O11="None",40,IF('Market Input'!O11="Weak",30,IF('Market Input'!O11="Moderate",15,5)))) | L11: =IF('Market Input'!P11="",0,IF('Market Input'!P11="None",5,IF('Market Input'!P11="Contact Only",15,IF('Market Input'!P11="Active Advocate",30,40)))) | M11: =IF('Market Input'!D11="","",ROUND((C11*0.15+D11*0.15+E11*0.15+F11*0.15+G11*0.10+H11*0.10+I11*0.05+J11*0.05+K11*0.05+L11*0.05)/40*100,0)) | N11: =IF(M11="","",IF(M11>=80,"A",IF(M11>=65,"B",IF(M11>=50,"C",IF(M11>=35,"D","F")))))
A12: ='Market Input'!A12 | B12: ='Market Input'!D12 | C12: =IF('Market Input'!E12="",0,IF('Market Input'!E12<25000,5,IF('Market Input'!E12<100000,15,IF('Market Input'!E12<250000,30,IF('Market Input'!E12<1000000,50,40))))) | D12: =IF('Market Input'!F12="",0,IF('Market Input'!F12<40000,5,IF('Market Input'!F12<60000,20,IF('Market Input'!F12<80000,40,IF('Market Input'!F12<100000,60,50))))) | E12: =IF(OR('Market Input'!J12="",'Market Input'!E12="",'Market Input'!E12=0),0,LET(density,'Market Input'!J12/'Market Input'!E12*100000,IF(density<2,10,IF(density<5,30,IF(density<8,40,20))))) | F12: =IF('Market Input'!L12="",0,IF('Market Input'!L12<100,5,IF('Market Input'!L12<500,20,IF('Market Input'!L12<1000,35,40)))) | G12: =IF('Market Input'!M12="",0,IF('Market Input'!M12<120,10,IF('Market Input'!M12<180,25,IF('Market Input'!M12<240,35,40)))) | H12: =IF('Market Input'!G12="",0,IF('Market Input'!G12="Rural",35,IF('Market Input'!G12="Suburban",35,IF('Market Input'!G12="Urban",25,30)))) | I12: =IF('Market Input'!H12="",0,IF('Market Input'!H12="Agricultural",40,IF('Market Input'!H12="Mixed",30,IF('Market Input'!H12="Tourism",30,IF('Market Input'!H12="Service",25,IF('Market Input'!H12="Technical",20,15)))))) | J12: =IF('Market Input'!R12="",0,IF('Market Input'!R12="None",0,IF('Market Input'!R12="Low",10,IF('Market Input'!R12="Moderate",25,IF('Market Input'!R12="High",35,40))))) | K12: =IF('Market Input'!O12="",0,IF('Market Input'!O12="None",40,IF('Market Input'!O12="Weak",30,IF('Market Input'!O12="Moderate",15,5)))) | L12: =IF('Market Input'!P12="",0,IF('Market Input'!P12="None",5,IF('Market Input'!P12="Contact Only",15,IF('Market Input'!P12="Active Advocate",30,40)))) | M12: =IF('Market Input'!D12="","",ROUND((C12*0.15+D12*0.15+E12*0.15+F12*0.15+G12*0.10+H12*0.10+I12*0.05+J12*0.05+K12*0.05+L12*0.05)/40*100,0)) | N12: =IF(M12="","",IF(M12>=80,"A",IF(M12>=65,"B",IF(M12>=50,"C",IF(M12>=35,"D","F")))))
A13: ='Market Input'!A13 | B13: ='Market Input'!D13 | C13: =IF('Market Input'!E13="",0,IF('Market Input'!E13<25000,5,IF('Market Input'!E13<100000,15,IF('Market Input'!E13<250000,30,IF('Market Input'!E13<1000000,50,40))))) | D13: =IF('Market Input'!F13="",0,IF('Market Input'!F13<40000,5,IF('Market Input'!F13<60000,20,IF('Market Input'!F13<80000,40,IF('Market Input'!F13<100000,60,50))))) | E13: =IF(OR('Market Input'!J13="",'Market Input'!E13="",'Market Input'!E13=0),0,LET(density,'Market Input'!J13/'Market Input'!E13*100000,IF(density<2,10,IF(density<5,30,IF(density<8,40,20))))) | F13: =IF('Market Input'!L13="",0,IF('Market Input'!L13<100,5,IF('Market Input'!L13<500,20,IF('Market Input'!L13<1000,35,40)))) | G13: =IF('Market Input'!M13="",0,IF('Market Input'!M13<120,10,IF('Market Input'!M13<180,25,IF('Market Input'!M13<240,35,40)))) | H13: =IF('Market Input'!G13="",0,IF('Market Input'!G13="Rural",35,IF('Market Input'!G13="Suburban",35,IF('Market Input'!G13="Urban",25,30)))) | I13: =IF('Market Input'!H13="",0,IF('Market Input'!H13="Agricultural",40,IF('Market Input'!H13="Mixed",30,IF('Market Input'!H13="Tourism",30,IF('Market Input'!H13="Service",25,IF('Market Input'!H13="Technical",20,15)))))) | J13: =IF('Market Input'!R13="",0,IF('Market Input'!R13="None",0,IF('Market Input'!R13="Low",10,IF('Market Input'!R13="Moderate",25,IF('Market Input'!R13="High",35,40))))) | K13: =IF('Market Input'!O13="",0,IF('Market Input'!O13="None",40,IF('Market Input'!O13="Weak",30,IF('Market Input'!O13="Moderate",15,5)))) | L13: =IF('Market Input'!P13="",0,IF('Market Input'!P13="None",5,IF('Market Input'!P13="Contact Only",15,IF('Market Input'!P13="Active Advocate",30,40)))) | M13: =IF('Market Input'!D13="","",ROUND((C13*0.15+D13*0.15+E13*0.15+F13*0.15+G13*0.10+H13*0.10+I13*0.05+J13*0.05+K13*0.05+L13*0.05)/40*100,0)) | N13: =IF(M13="","",IF(M13>=80,"A",IF(M13>=65,"B",IF(M13>=50,"C",IF(M13>=35,"D","F")))))
A14: ='Market Input'!A14 | B14: ='Market Input'!D14 | C14: =IF('Market Input'!E14="",0,IF('Market Input'!E14<25000,5,IF('Market Input'!E14<100000,15,IF('Market Input'!E14<250000,30,IF('Market Input'!E14<1000000,50,40))))) | D14: =IF('Market Input'!F14="",0,IF('Market Input'!F14<40000,5,IF('Market Input'!F14<60000,20,IF('Market Input'!F14<80000,40,IF('Market Input'!F14<100000,60,50))))) | E14: =IF(OR('Market Input'!J14="",'Market Input'!E14="",'Market Input'!E14=0),0,LET(density,'Market Input'!J14/'Market Input'!E14*100000,IF(density<2,10,IF(density<5,30,IF(density<8,40,20))))) | F14: =IF('Market Input'!L14="",0,IF('Market Input'!L14<100,5,IF('Market Input'!L14<500,20,IF('Market Input'!L14<1000,35,40)))) | G14: =IF('Market Input'!M14="",0,IF('Market Input'!M14<120,10,IF('Market Input'!M14<180,25,IF('Market Input'!M14<240,35,40)))) | H14: =IF('Market Input'!G14="",0,IF('Market Input'!G14="Rural",35,IF('Market Input'!G14="Suburban",35,IF('Market Input'!G14="Urban",25,30)))) | I14: =IF('Market Input'!H14="",0,IF('Market Input'!H14="Agricultural",40,IF('Market Input'!H14="Mixed",30,IF('Market Input'!H14="Tourism",30,IF('Market Input'!H14="Service",25,IF('Market Input'!H14="Technical",20,15)))))) | J14: =IF('Market Input'!R14="",0,IF('Market Input'!R14="None",0,IF('Market Input'!R14="Low",10,IF('Market Input'!R14="Moderate",25,IF('Market Input'!R14="High",35,40))))) | K14: =IF('Market Input'!O14="",0,IF('Market Input'!O14="None",40,IF('Market Input'!O14="Weak",30,IF('Market Input'!O14="Moderate",15,5)))) | L14: =IF('Market Input'!P14="",0,IF('Market Input'!P14="None",5,IF('Market Input'!P14="Contact Only",15,IF('Market Input'!P14="Active Advocate",30,40)))) | M14: =IF('Market Input'!D14="","",ROUND((C14*0.15+D14*0.15+E14*0.15+F14*0.15+G14*0.10+H14*0.10+I14*0.05+J14*0.05+K14*0.05+L14*0.05)/40*100,0)) | N14: =IF(M14="","",IF(M14>=80,"A",IF(M14>=65,"B",IF(M14>=50,"C",IF(M14>=35,"D","F")))))
A15: ='Market Input'!A15 | B15: ='Market Input'!D15 | C15: =IF('Market Input'!E15="",0,IF('Market Input'!E15<25000,5,IF('Market Input'!E15<100000,15,IF('Market Input'!E15<250000,30,IF('Market Input'!E15<1000000,50,40))))) | D15: =IF('Market Input'!F15="",0,IF('Market Input'!F15<40000,5,IF('Market Input'!F15<60000,20,IF('Market Input'!F15<80000,40,IF('Market Input'!F15<100000,60,50))))) | E15: =IF(OR('Market Input'!J15="",'Market Input'!E15="",'Market Input'!E15=0),0,LET(density,'Market Input'!J15/'Market Input'!E15*100000,IF(density<2,10,IF(density<5,30,IF(density<8,40,20))))) | F15: =IF('Market Input'!L15="",0,IF('Market Input'!L15<100,5,IF('Market Input'!L15<500,20,IF('Market Input'!L15<1000,35,40)))) | G15: =IF('Market Input'!M15="",0,IF('Market Input'!M15<120,10,IF('Market Input'!M15<180,25,IF('Market Input'!M15<240,35,40)))) | H15: =IF('Market Input'!G15="",0,IF('Market Input'!G15="Rural",35,IF('Market Input'!G15="Suburban",35,IF('Market Input'!G15="Urban",25,30)))) | I15: =IF('Market Input'!H15="",0,IF('Market Input'!H15="Agricultural",40,IF('Market Input'!H15="Mixed",30,IF('Market Input'!H15="Tourism",30,IF('Market Input'!H15="Service",25,IF('Market Input'!H15="Technical",20,15)))))) | J15: =IF('Market Input'!R15="",0,IF('Market Input'!R15="None",0,IF('Market Input'!R15="Low",10,IF('Market Input'!R15="Moderate",25,IF('Market Input'!R15="High",35,40))))) | K15: =IF('Market Input'!O15="",0,IF('Market Input'!O15="None",40,IF('Market Input'!O15="Weak",30,IF('Market Input'!O15="Moderate",15,5)))) | L15: =IF('Market Input'!P15="",0,IF('Market Input'!P15="None",5,IF('Market Input'!P15="Contact Only",15,IF('Market Input'!P15="Active Advocate",30,40)))) | M15: =IF('Market Input'!D15="","",ROUND((C15*0.15+D15*0.15+E15*0.15+F15*0.15+G15*0.10+H15*0.10+I15*0.05+J15*0.05+K15*0.05+L15*0.05)/40*100,0)) | N15: =IF(M15="","",IF(M15>=80,"A",IF(M15>=65,"B",IF(M15>=50,"C",IF(M15>=35,"D","F")))))
A16: ='Market Input'!A16 | B16: ='Market Input'!D16 | C16: =IF('Market Input'!E16="",0,IF('Market Input'!E16<25000,5,IF('Market Input'!E16<100000,15,IF('Market Input'!E16<250000,30,IF('Market Input'!E16<1000000,50,40))))) | D16: =IF('Market Input'!F16="",0,IF('Market Input'!F16<40000,5,IF('Market Input'!F16<60000,20,IF('Market Input'!F16<80000,40,IF('Market Input'!F16<100000,60,50))))) | E16: =IF(OR('Market Input'!J16="",'Market Input'!E16="",'Market Input'!E16=0),0,LET(density,'Market Input'!J16/'Market Input'!E16*100000,IF(density<2,10,IF(density<5,30,IF(density<8,40,20))))) | F16: =IF('Market Input'!L16="",0,IF('Market Input'!L16<100,5,IF('Market Input'!L16<500,20,IF('Market Input'!L16<1000,35,40)))) | G16: =IF('Market Input'!M16="",0,IF('Market Input'!M16<120,10,IF('Market Input'!M16<180,25,IF('Market Input'!M16<240,35,40)))) | H16: =IF('Market Input'!G16="",0,IF('Market Input'!G16="Rural",35,IF('Market Input'!G16="Suburban",35,IF('Market Input'!G16="Urban",25,30)))) | I16: =IF('Market Input'!H16="",0,IF('Market Input'!H16="Agricultural",40,IF('Market Input'!H16="Mixed",30,IF('Market Input'!H16="Tourism",30,IF('Market Input'!H16="Service",25,IF('Market Input'!H16="Technical",20,15)))))) | J16: =IF('Market Input'!R16="",0,IF('Market Input'!R16="None",0,IF('Market Input'!R16="Low",10,IF('Market Input'!R16="Moderate",25,IF('Market Input'!R16="High",35,40))))) | K16: =IF('Market Input'!O16="",0,IF('Market Input'!O16="None",40,IF('Market Input'!O16="Weak",30,IF('Market Input'!O16="Moderate",15,5)))) | L16: =IF('Market Input'!P16="",0,IF('Market Input'!P16="None",5,IF('Market Input'!P16="Contact Only",15,IF('Market Input'!P16="Active Advocate",30,40)))) | M16: =IF('Market Input'!D16="","",ROUND((C16*0.15+D16*0.15+E16*0.15+F16*0.15+G16*0.10+H16*0.10+I16*0.05+J16*0.05+K16*0.05+L16*0.05)/40*100,0)) | N16: =IF(M16="","",IF(M16>=80,"A",IF(M16>=65,"B",IF(M16>=50,"C",IF(M16>=35,"D","F")))))
... A24: ='Market Input'!A24 | B24: ='Market Input'!D24 | C24: =IF('Market Input'!E24="",0,IF('Market Input'!E24<25000,5,IF('Market Input'!E24<100000,15,IF('Market Input'!E24<250000,30,IF('Market Input'!E24<1000000,50,40))))) | D24: =IF('Market Input'!F24="",0,IF('Market Input'!F24<40000,5,IF('Market Input'!F24<60000,20,IF('Market Input'!F24<80000,40,IF('Market Input'!F24<100000,60,50))))) | E24: =IF(OR('Market Input'!J24="",'Market Input'!E24="",'Market Input'!E24=0),0,LET(density,'Market Input'!J24/'Market Input'!E24*100000,IF(density<2,10,IF(density<5,30,IF(density<8,40,20))))) | F24: =IF('Market Input'!L24="",0,IF('Market Input'!L24<100,5,IF('Market Input'!L24<500,20,IF('Market Input'!L24<1000,35,40)))) | G24: =IF('Market Input'!M24="",0,IF('Market Input'!M24<120,10,IF('Market Input'!M24<180,25,IF('Market Input'!M24<240,35,40)))) | H24: =IF('Market Input'!G24="",0,IF('Market Input'!G24="Rural",35,IF('Market Input'!G24="Suburban",35,IF('Market Input'!G24="Urban",25,30)))) | I24: =IF('Market Input'!H24="",0,IF('Market Input'!H24="Agricultural",40,IF('Market Input'!H24="Mixed",30,IF('Market Input'!H24="Tourism",30,IF('Market Input'!H24="Service",25,IF('Market Input'!H24="Technical",20,15)))))) | J24: =IF('Market Input'!R24="",0,IF('Market Input'!R24="None",0,IF('Market Input'!R24="Low",10,IF('Market Input'!R24="Moderate",25,IF('Market Input'!R24="High",35,40))))) | K24: =IF('Market Input'!O24="",0,IF('Market Input'!O24="None",40,IF('Market Input'!O24="Weak",30,IF('Market Input'!O24="Moderate",15,5)))) | L24: =IF('Market Input'!P24="",0,IF('Market Input'!P24="None",5,IF('Market Input'!P24="Contact Only",15,IF('Market Input'!P24="Active Advocate",30,40)))) | M24: =IF('Market Input'!D24="","",ROUND((C24*0.15+D24*0.15+E24*0.15+F24*0.15+G24*0.10+H24*0.10+I24*0.05+J24*0.05+K24*0.05+L24*0.05)/40*100,0)) | N24: =IF(M24="","",IF(M24>=80,"A",IF(M24>=65,"B",IF(M24>=50,"C",IF(M24>=35,"D","F")))))
A27: FOOD TRUCK SCORING
A29: Market ID | B29: City/County | C29: Pop Score | D29: Income Score | E29: FT Density Score | F29: University Score | G29: Regulatory Score | H29: Tourism Score | I29: Community Fit | J29: Competition | K29: Champion Bonus | L29: Climate Score | M29: FT TOTAL SCORE | N29: FT Grade
A30: ='Market Input'!A5 | B30: ='Market Input'!D5 | C30: =IF('Market Input'!E5="",0,IF('Market Input'!E5<25000,5,IF('Market Input'!E5<100000,10,IF('Market Input'!E5<250000,25,IF('Market Input'!E5<1000000,45,50))))) | D30: =IF('Market Input'!F5="",0,IF('Market Input'!F5<40000,15,IF('Market Input'!F5<60000,25,IF('Market Input'!F5<80000,35,40)))) | E30: =IF(OR('Market Input'!K5="",'Market Input'!E5="",'Market Input'!E5=0),0,LET(density,'Market Input'!K5/'Market Input'!E5*100000,IF(density<1,10,IF(density<5,25,IF(density<15,40,30))))) | F30: =IF('Market Input'!N5="",0,IF('Market Input'!N5=0,0,IF('Market Input'!N5<5000,10,IF('Market Input'!N5<15000,25,IF('Market Input'!N5<30000,35,40))))) | G30: =IF('Market Input'!Q5="",0,IF('Market Input'!Q5="Very Friendly",40,IF('Market Input'!Q5="Friendly",30,IF('Market Input'!Q5="Moderate",20,IF('Market Input'!Q5="Restrictive",10,0))))) | H30: =IF('Market Input'!R5="",0,IF('Market Input'!R5="None",0,IF('Market Input'!R5="Low",10,IF('Market Input'!R5="Moderate",25,IF('Market Input'!R5="High",35,40))))) | I30: =IF('Market Input'!G5="",0,IF('Market Input'!G5="Urban",40,IF('Market Input'!G5="College Town",38,IF('Market Input'!G5="Suburban",25,10)))) | J30: =IF('Market Input'!O5="",0,IF('Market Input'!O5="None",40,IF('Market Input'!O5="Weak",30,IF('Market Input'!O5="Moderate",15,5)))) | K30: =IF('Market Input'!P5="",0,IF('Market Input'!P5="None",5,IF('Market Input'!P5="Contact Only",15,IF('Market Input'!P5="Active Advocate",30,40)))) | L30: =IF('Market Input'!M5="",0,IF('Market Input'!M5<120,10,IF('Market Input'!M5<180,20,IF('Market Input'!M5<240,30,40)))) | M30: =IF('Market Input'!D5="","",ROUND((C30*0.20+D30*0.10+E30*0.10+F30*0.15+G30*0.10+H30*0.10+I30*0.10+J30*0.05+K30*0.05+L30*0.05)/40*100,0)) | N30: =IF(M30="","",IF(M30>=80,"A",IF(M30>=65,"B",IF(M30>=50,"C",IF(M30>=35,"D","F")))))
A31: ='Market Input'!A6 | B31: ='Market Input'!D6 | C31: =IF('Market Input'!E6="",0,IF('Market Input'!E6<25000,5,IF('Market Input'!E6<100000,10,IF('Market Input'!E6<250000,25,IF('Market Input'!E6<1000000,45,50))))) | D31: =IF('Market Input'!F6="",0,IF('Market Input'!F6<40000,15,IF('Market Input'!F6<60000,25,IF('Market Input'!F6<80000,35,40)))) | E31: =IF(OR('Market Input'!K6="",'Market Input'!E6="",'Market Input'!E6=0),0,LET(density,'Market Input'!K6/'Market Input'!E6*100000,IF(density<1,10,IF(density<5,25,IF(density<15,40,30))))) | F31: =IF('Market Input'!N6="",0,IF('Market Input'!N6=0,0,IF('Market Input'!N6<5000,10,IF('Market Input'!N6<15000,25,IF('Market Input'!N6<30000,35,40))))) | G31: =IF('Market Input'!Q6="",0,IF('Market Input'!Q6="Very Friendly",40,IF('Market Input'!Q6="Friendly",30,IF('Market Input'!Q6="Moderate",20,IF('Market Input'!Q6="Restrictive",10,0))))) | H31: =IF('Market Input'!R6="",0,IF('Market Input'!R6="None",0,IF('Market Input'!R6="Low",10,IF('Market Input'!R6="Moderate",25,IF('Market Input'!R6="High",35,40))))) | I31: =IF('Market Input'!G6="",0,IF('Market Input'!G6="Urban",40,IF('Market Input'!G6="College Town",38,IF('Market Input'!G6="Suburban",25,10)))) | J31: =IF('Market Input'!O6="",0,IF('Market Input'!O6="None",40,IF('Market Input'!O6="Weak",30,IF('Market Input'!O6="Moderate",15,5)))) | K31: =IF('Market Input'!P6="",0,IF('Market Input'!P6="None",5,IF('Market Input'!P6="Contact Only",15,IF('Market Input'!P6="Active Advocate",30,40)))) | L31: =IF('Market Input'!M6="",0,IF('Market Input'!M6<120,10,IF('Market Input'!M6<180,20,IF('Market Input'!M6<240,30,40)))) | M31: =IF('Market Input'!D6="","",ROUND((C31*0.20+D31*0.10+E31*0.10+F31*0.15+G31*0.10+H31*0.10+I31*0.10+J31*0.05+K31*0.05+L31*0.05)/40*100,0)) | N31: =IF(M31="","",IF(M31>=80,"A",IF(M31>=65,"B",IF(M31>=50,"C",IF(M31>=35,"D","F")))))
A32: ='Market Input'!A7 | B32: ='Market Input'!D7 | C32: =IF('Market Input'!E7="",0,IF('Market Input'!E7<25000,5,IF('Market Input'!E7<100000,10,IF('Market Input'!E7<250000,25,IF('Market Input'!E7<1000000,45,50))))) | D32: =IF('Market Input'!F7="",0,IF('Market Input'!F7<40000,15,IF('Market Input'!F7<60000,25,IF('Market Input'!F7<80000,35,40)))) | E32: =IF(OR('Market Input'!K7="",'Market Input'!E7="",'Market Input'!E7=0),0,LET(density,'Market Input'!K7/'Market Input'!E7*100000,IF(density<1,10,IF(density<5,25,IF(density<15,40,30))))) | F32: =IF('Market Input'!N7="",0,IF('Market Input'!N7=0,0,IF('Market Input'!N7<5000,10,IF('Market Input'!N7<15000,25,IF('Market Input'!N7<30000,35,40))))) | G32: =IF('Market Input'!Q7="",0,IF('Market Input'!Q7="Very Friendly",40,IF('Market Input'!Q7="Friendly",30,IF('Market Input'!Q7="Moderate",20,IF('Market Input'!Q7="Restrictive",10,0))))) | H32: =IF('Market Input'!R7="",0,IF('Market Input'!R7="None",0,IF('Market Input'!R7="Low",10,IF('Market Input'!R7="Moderate",25,IF('Market Input'!R7="High",35,40))))) | I32: =IF('Market Input'!G7="",0,IF('Market Input'!G7="Urban",40,IF('Market Input'!G7="College Town",38,IF('Market Input'!G7="Suburban",25,10)))) | J32: =IF('Market Input'!O7="",0,IF('Market Input'!O7="None",40,IF('Market Input'!O7="Weak",30,IF('Market Input'!O7="Moderate",15,5)))) | K32: =IF('Market Input'!P7="",0,IF('Market Input'!P7="None",5,IF('Market Input'!P7="Contact Only",15,IF('Market Input'!P7="Active Advocate",30,40)))) | L32: =IF('Market Input'!M7="",0,IF('Market Input'!M7<120,10,IF('Market Input'!M7<180,20,IF('Market Input'!M7<240,30,40)))) | M32: =IF('Market Input'!D7="","",ROUND((C32*0.20+D32*0.10+E32*0.10+F32*0.15+G32*0.10+H32*0.10+I32*0.10+J32*0.05+K32*0.05+L32*0.05)/40*100,0)) | N32: =IF(M32="","",IF(M32>=80,"A",IF(M32>=65,"B",IF(M32>=50,"C",IF(M32>=35,"D","F")))))
A33: ='Market Input'!A8 | B33: ='Market Input'!D8 | C33: =IF('Market Input'!E8="",0,IF('Market Input'!E8<25000,5,IF('Market Input'!E8<100000,10,IF('Market Input'!E8<250000,25,IF('Market Input'!E8<1000000,45,50))))) | D33: =IF('Market Input'!F8="",0,IF('Market Input'!F8<40000,15,IF('Market Input'!F8<60000,25,IF('Market Input'!F8<80000,35,40)))) | E33: =IF(OR('Market Input'!K8="",'Market Input'!E8="",'Market Input'!E8=0),0,LET(density,'Market Input'!K8/'Market Input'!E8*100000,IF(density<1,10,IF(density<5,25,IF(density<15,40,30))))) | F33: =IF('Market Input'!N8="",0,IF('Market Input'!N8=0,0,IF('Market Input'!N8<5000,10,IF('Market Input'!N8<15000,25,IF('Market Input'!N8<30000,35,40))))) | G33: =IF('Market Input'!Q8="",0,IF('Market Input'!Q8="Very Friendly",40,IF('Market Input'!Q8="Friendly",30,IF('Market Input'!Q8="Moderate",20,IF('Market Input'!Q8="Restrictive",10,0))))) | H33: =IF('Market Input'!R8="",0,IF('Market Input'!R8="None",0,IF('Market Input'!R8="Low",10,IF('Market Input'!R8="Moderate",25,IF('Market Input'!R8="High",35,40))))) | I33: =IF('Market Input'!G8="",0,IF('Market Input'!G8="Urban",40,IF('Market Input'!G8="College Town",38,IF('Market Input'!G8="Suburban",25,10)))) | J33: =IF('Market Input'!O8="",0,IF('Market Input'!O8="None",40,IF('Market Input'!O8="Weak",30,IF('Market Input'!O8="Moderate",15,5)))) | K33: =IF('Market Input'!P8="",0,IF('Market Input'!P8="None",5,IF('Market Input'!P8="Contact Only",15,IF('Market Input'!P8="Active Advocate",30,40)))) | L33: =IF('Market Input'!M8="",0,IF('Market Input'!M8<120,10,IF('Market Input'!M8<180,20,IF('Market Input'!M8<240,30,40)))) | M33: =IF('Market Input'!D8="","",ROUND((C33*0.20+D33*0.10+E33*0.10+F33*0.15+G33*0.10+H33*0.10+I33*0.10+J33*0.05+K33*0.05+L33*0.05)/40*100,0)) | N33: =IF(M33="","",IF(M33>=80,"A",IF(M33>=65,"B",IF(M33>=50,"C",IF(M33>=35,"D","F")))))
A34: ='Market Input'!A9 | B34: ='Market Input'!D9 | C34: =IF('Market Input'!E9="",0,IF('Market Input'!E9<25000,5,IF('Market Input'!E9<100000,10,IF('Market Input'!E9<250000,25,IF('Market Input'!E9<1000000,45,50))))) | D34: =IF('Market Input'!F9="",0,IF('Market Input'!F9<40000,15,IF('Market Input'!F9<60000,25,IF('Market Input'!F9<80000,35,40)))) | E34: =IF(OR('Market Input'!K9="",'Market Input'!E9="",'Market Input'!E9=0),0,LET(density,'Market Input'!K9/'Market Input'!E9*100000,IF(density<1,10,IF(density<5,25,IF(density<15,40,30))))) | F34: =IF('Market Input'!N9="",0,IF('Market Input'!N9=0,0,IF('Market Input'!N9<5000,10,IF('Market Input'!N9<15000,25,IF('Market Input'!N9<30000,35,40))))) | G34: =IF('Market Input'!Q9="",0,IF('Market Input'!Q9="Very Friendly",40,IF('Market Input'!Q9="Friendly",30,IF('Market Input'!Q9="Moderate",20,IF('Market Input'!Q9="Restrictive",10,0))))) | H34: =IF('Market Input'!R9="",0,IF('Market Input'!R9="None",0,IF('Market Input'!R9="Low",10,IF('Market Input'!R9="Moderate",25,IF('Market Input'!R9="High",35,40))))) | I34: =IF('Market Input'!G9="",0,IF('Market Input'!G9="Urban",40,IF('Market Input'!G9="College Town",38,IF('Market Input'!G9="Suburban",25,10)))) | J34: =IF('Market Input'!O9="",0,IF('Market Input'!O9="None",40,IF('Market Input'!O9="Weak",30,IF('Market Input'!O9="Moderate",15,5)))) | K34: =IF('Market Input'!P9="",0,IF('Market Input'!P9="None",5,IF('Market Input'!P9="Contact Only",15,IF('Market Input'!P9="Active Advocate",30,40)))) | L34: =IF('Market Input'!M9="",0,IF('Market Input'!M9<120,10,IF('Market Input'!M9<180,20,IF('Market Input'!M9<240,30,40)))) | M34: =IF('Market Input'!D9="","",ROUND((C34*0.20+D34*0.10+E34*0.10+F34*0.15+G34*0.10+H34*0.10+I34*0.10+J34*0.05+K34*0.05+L34*0.05)/40*100,0)) | N34: =IF(M34="","",IF(M34>=80,"A",IF(M34>=65,"B",IF(M34>=50,"C",IF(M34>=35,"D","F")))))
A35: ='Market Input'!A10 | B35: ='Market Input'!D10 | C35: =IF('Market Input'!E10="",0,IF('Market Input'!E10<25000,5,IF('Market Input'!E10<100000,10,IF('Market Input'!E10<250000,25,IF('Market Input'!E10<1000000,45,50))))) | D35: =IF('Market Input'!F10="",0,IF('Market Input'!F10<40000,15,IF('Market Input'!F10<60000,25,IF('Market Input'!F10<80000,35,40)))) | E35: =IF(OR('Market Input'!K10="",'Market Input'!E10="",'Market Input'!E10=0),0,LET(density,'Market Input'!K10/'Market Input'!E10*100000,IF(density<1,10,IF(density<5,25,IF(density<15,40,30))))) | F35: =IF('Market Input'!N10="",0,IF('Market Input'!N10=0,0,IF('Market Input'!N10<5000,10,IF('Market Input'!N10<15000,25,IF('Market Input'!N10<30000,35,40))))) | G35: =IF('Market Input'!Q10="",0,IF('Market Input'!Q10="Very Friendly",40,IF('Market Input'!Q10="Friendly",30,IF('Market Input'!Q10="Moderate",20,IF('Market Input'!Q10="Restrictive",10,0))))) | H35: =IF('Market Input'!R10="",0,IF('Market Input'!R10="None",0,IF('Market Input'!R10="Low",10,IF('Market Input'!R10="Moderate",25,IF('Market Input'!R10="High",35,40))))) | I35: =IF('Market Input'!G10="",0,IF('Market Input'!G10="Urban",40,IF('Market Input'!G10="College Town",38,IF('Market Input'!G10="Suburban",25,10)))) | J35: =IF('Market Input'!O10="",0,IF('Market Input'!O10="None",40,IF('Market Input'!O10="Weak",30,IF('Market Input'!O10="Moderate",15,5)))) | K35: =IF('Market Input'!P10="",0,IF('Market Input'!P10="None",5,IF('Market Input'!P10="Contact Only",15,IF('Market Input'!P10="Active Advocate",30,40)))) | L35: =IF('Market Input'!M10="",0,IF('Market Input'!M10<120,10,IF('Market Input'!M10<180,20,IF('Market Input'!M10<240,30,40)))) | M35: =IF('Market Input'!D10="","",ROUND((C35*0.20+D35*0.10+E35*0.10+F35*0.15+G35*0.10+H35*0.10+I35*0.10+J35*0.05+K35*0.05+L35*0.05)/40*100,0)) | N35: =IF(M35="","",IF(M35>=80,"A",IF(M35>=65,"B",IF(M35>=50,"C",IF(M35>=35,"D","F")))))
A36: ='Market Input'!A11 | B36: ='Market Input'!D11 | C36: =IF('Market Input'!E11="",0,IF('Market Input'!E11<25000,5,IF('Market Input'!E11<100000,10,IF('Market Input'!E11<250000,25,IF('Market Input'!E11<1000000,45,50))))) | D36: =IF('Market Input'!F11="",0,IF('Market Input'!F11<40000,15,IF('Market Input'!F11<60000,25,IF('Market Input'!F11<80000,35,40)))) | E36: =IF(OR('Market Input'!K11="",'Market Input'!E11="",'Market Input'!E11=0),0,LET(density,'Market Input'!K11/'Market Input'!E11*100000,IF(density<1,10,IF(density<5,25,IF(density<15,40,30))))) | F36: =IF('Market Input'!N11="",0,IF('Market Input'!N11=0,0,IF('Market Input'!N11<5000,10,IF('Market Input'!N11<15000,25,IF('Market Input'!N11<30000,35,40))))) | G36: =IF('Market Input'!Q11="",0,IF('Market Input'!Q11="Very Friendly",40,IF('Market Input'!Q11="Friendly",30,IF('Market Input'!Q11="Moderate",20,IF('Market Input'!Q11="Restrictive",10,0))))) | H36: =IF('Market Input'!R11="",0,IF('Market Input'!R11="None",0,IF('Market Input'!R11="Low",10,IF('Market Input'!R11="Moderate",25,IF('Market Input'!R11="High",35,40))))) | I36: =IF('Market Input'!G11="",0,IF('Market Input'!G11="Urban",40,IF('Market Input'!G11="College Town",38,IF('Market Input'!G11="Suburban",25,10)))) | J36: =IF('Market Input'!O11="",0,IF('Market Input'!O11="None",40,IF('Market Input'!O11="Weak",30,IF('Market Input'!O11="Moderate",15,5)))) | K36: =IF('Market Input'!P11="",0,IF('Market Input'!P11="None",5,IF('Market Input'!P11="Contact Only",15,IF('Market Input'!P11="Active Advocate",30,40)))) | L36: =IF('Market Input'!M11="",0,IF('Market Input'!M11<120,10,IF('Market Input'!M11<180,20,IF('Market Input'!M11<240,30,40)))) | M36: =IF('Market Input'!D11="","",ROUND((C36*0.20+D36*0.10+E36*0.10+F36*0.15+G36*0.10+H36*0.10+I36*0.10+J36*0.05+K36*0.05+L36*0.05)/40*100,0)) | N36: =IF(M36="","",IF(M36>=80,"A",IF(M36>=65,"B",IF(M36>=50,"C",IF(M36>=35,"D","F")))))
A37: ='Market Input'!A12 | B37: ='Market Input'!D12 | C37: =IF('Market Input'!E12="",0,IF('Market Input'!E12<25000,5,IF('Market Input'!E12<100000,10,IF('Market Input'!E12<250000,25,IF('Market Input'!E12<1000000,45,50))))) | D37: =IF('Market Input'!F12="",0,IF('Market Input'!F12<40000,15,IF('Market Input'!F12<60000,25,IF('Market Input'!F12<80000,35,40)))) | E37: =IF(OR('Market Input'!K12="",'Market Input'!E12="",'Market Input'!E12=0),0,LET(density,'Market Input'!K12/'Market Input'!E12*100000,IF(density<1,10,IF(density<5,25,IF(density<15,40,30))))) | F37: =IF('Market Input'!N12="",0,IF('Market Input'!N12=0,0,IF('Market Input'!N12<5000,10,IF('Market Input'!N12<15000,25,IF('Market Input'!N12<30000,35,40))))) | G37: =IF('Market Input'!Q12="",0,IF('Market Input'!Q12="Very Friendly",40,IF('Market Input'!Q12="Friendly",30,IF('Market Input'!Q12="Moderate",20,IF('Market Input'!Q12="Restrictive",10,0))))) | H37: =IF('Market Input'!R12="",0,IF('Market Input'!R12="None",0,IF('Market Input'!R12="Low",10,IF('Market Input'!R12="Moderate",25,IF('Market Input'!R12="High",35,40))))) | I37: =IF('Market Input'!G12="",0,IF('Market Input'!G12="Urban",40,IF('Market Input'!G12="College Town",38,IF('Market Input'!G12="Suburban",25,10)))) | J37: =IF('Market Input'!O12="",0,IF('Market Input'!O12="None",40,IF('Market Input'!O12="Weak",30,IF('Market Input'!O12="Moderate",15,5)))) | K37: =IF('Market Input'!P12="",0,IF('Market Input'!P12="None",5,IF('Market Input'!P12="Contact Only",15,IF('Market Input'!P12="Active Advocate",30,40)))) | L37: =IF('Market Input'!M12="",0,IF('Market Input'!M12<120,10,IF('Market Input'!M12<180,20,IF('Market Input'!M12<240,30,40)))) | M37: =IF('Market Input'!D12="","",ROUND((C37*0.20+D37*0.10+E37*0.10+F37*0.15+G37*0.10+H37*0.10+I37*0.10+J37*0.05+K37*0.05+L37*0.05)/40*100,0)) | N37: =IF(M37="","",IF(M37>=80,"A",IF(M37>=65,"B",IF(M37>=50,"C",IF(M37>=35,"D","F")))))
A38: ='Market Input'!A13 | B38: ='Market Input'!D13 | C38: =IF('Market Input'!E13="",0,IF('Market Input'!E13<25000,5,IF('Market Input'!E13<100000,10,IF('Market Input'!E13<250000,25,IF('Market Input'!E13<1000000,45,50))))) | D38: =IF('Market Input'!F13="",0,IF('Market Input'!F13<40000,15,IF('Market Input'!F13<60000,25,IF('Market Input'!F13<80000,35,40)))) | E38: =IF(OR('Market Input'!K13="",'Market Input'!E13="",'Market Input'!E13=0),0,LET(density,'Market Input'!K13/'Market Input'!E13*100000,IF(density<1,10,IF(density<5,25,IF(density<15,40,30))))) | F38: =IF('Market Input'!N13="",0,IF('Market Input'!N13=0,0,IF('Market Input'!N13<5000,10,IF('Market Input'!N13<15000,25,IF('Market Input'!N13<30000,35,40))))) | G38: =IF('Market Input'!Q13="",0,IF('Market Input'!Q13="Very Friendly",40,IF('Market Input'!Q13="Friendly",30,IF('Market Input'!Q13="Moderate",20,IF('Market Input'!Q13="Restrictive",10,0))))) | H38: =IF('Market Input'!R13="",0,IF('Market Input'!R13="None",0,IF('Market Input'!R13="Low",10,IF('Market Input'!R13="Moderate",25,IF('Market Input'!R13="High",35,40))))) | I38: =IF('Market Input'!G13="",0,IF('Market Input'!G13="Urban",40,IF('Market Input'!G13="College Town",38,IF('Market Input'!G13="Suburban",25,10)))) | J38: =IF('Market Input'!O13="",0,IF('Market Input'!O13="None",40,IF('Market Input'!O13="Weak",30,IF('Market Input'!O13="Moderate",15,5)))) | K38: =IF('Market Input'!P13="",0,IF('Market Input'!P13="None",5,IF('Market Input'!P13="Contact Only",15,IF('Market Input'!P13="Active Advocate",30,40)))) | L38: =IF('Market Input'!M13="",0,IF('Market Input'!M13<120,10,IF('Market Input'!M13<180,20,IF('Market Input'!M13<240,30,40)))) | M38: =IF('Market Input'!D13="","",ROUND((C38*0.20+D38*0.10+E38*0.10+F38*0.15+G38*0.10+H38*0.10+I38*0.10+J38*0.05+K38*0.05+L38*0.05)/40*100,0)) | N38: =IF(M38="","",IF(M38>=80,"A",IF(M38>=65,"B",IF(M38>=50,"C",IF(M38>=35,"D","F")))))
A39: ='Market Input'!A14 | B39: ='Market Input'!D14 | C39: =IF('Market Input'!E14="",0,IF('Market Input'!E14<25000,5,IF('Market Input'!E14<100000,10,IF('Market Input'!E14<250000,25,IF('Market Input'!E14<1000000,45,50))))) | D39: =IF('Market Input'!F14="",0,IF('Market Input'!F14<40000,15,IF('Market Input'!F14<60000,25,IF('Market Input'!F14<80000,35,40)))) | E39: =IF(OR('Market Input'!K14="",'Market Input'!E14="",'Market Input'!E14=0),0,LET(density,'Market Input'!K14/'Market Input'!E14*100000,IF(density<1,10,IF(density<5,25,IF(density<15,40,30))))) | F39: =IF('Market Input'!N14="",0,IF('Market Input'!N14=0,0,IF('Market Input'!N14<5000,10,IF('Market Input'!N14<15000,25,IF('Market Input'!N14<30000,35,40))))) | G39: =IF('Market Input'!Q14="",0,IF('Market Input'!Q14="Very Friendly",40,IF('Market Input'!Q14="Friendly",30,IF('Market Input'!Q14="Moderate",20,IF('Market Input'!Q14="Restrictive",10,0))))) | H39: =IF('Market Input'!R14="",0,IF('Market Input'!R14="None",0,IF('Market Input'!R14="Low",10,IF('Market Input'!R14="Moderate",25,IF('Market Input'!R14="High",35,40))))) | I39: =IF('Market Input'!G14="",0,IF('Market Input'!G14="Urban",40,IF('Market Input'!G14="College Town",38,IF('Market Input'!G14="Suburban",25,10)))) | J39: =IF('Market Input'!O14="",0,IF('Market Input'!O14="None",40,IF('Market Input'!O14="Weak",30,IF('Market Input'!O14="Moderate",15,5)))) | K39: =IF('Market Input'!P14="",0,IF('Market Input'!P14="None",5,IF('Market Input'!P14="Contact Only",15,IF('Market Input'!P14="Active Advocate",30,40)))) | L39: =IF('Market Input'!M14="",0,IF('Market Input'!M14<120,10,IF('Market Input'!M14<180,20,IF('Market Input'!M14<240,30,40)))) | M39: =IF('Market Input'!D14="","",ROUND((C39*0.20+D39*0.10+E39*0.10+F39*0.15+G39*0.10+H39*0.10+I39*0.10+J39*0.05+K39*0.05+L39*0.05)/40*100,0)) | N39: =IF(M39="","",IF(M39>=80,"A",IF(M39>=65,"B",IF(M39>=50,"C",IF(M39>=35,"D","F")))))
A40: ='Market Input'!A15 | B40: ='Market Input'!D15 | C40: =IF('Market Input'!E15="",0,IF('Market Input'!E15<25000,5,IF('Market Input'!E15<100000,10,IF('Market Input'!E15<250000,25,IF('Market Input'!E15<1000000,45,50))))) | D40: =IF('Market Input'!F15="",0,IF('Market Input'!F15<40000,15,IF('Market Input'!F15<60000,25,IF('Market Input'!F15<80000,35,40)))) | E40: =IF(OR('Market Input'!K15="",'Market Input'!E15="",'Market Input'!E15=0),0,LET(density,'Market Input'!K15/'Market Input'!E15*100000,IF(density<1,10,IF(density<5,25,IF(density<15,40,30))))) | F40: =IF('Market Input'!N15="",0,IF('Market Input'!N15=0,0,IF('Market Input'!N15<5000,10,IF('Market Input'!N15<15000,25,IF('Market Input'!N15<30000,35,40))))) | G40: =IF('Market Input'!Q15="",0,IF('Market Input'!Q15="Very Friendly",40,IF('Market Input'!Q15="Friendly",30,IF('Market Input'!Q15="Moderate",20,IF('Market Input'!Q15="Restrictive",10,0))))) | H40: =IF('Market Input'!R15="",0,IF('Market Input'!R15="None",0,IF('Market Input'!R15="Low",10,IF('Market Input'!R15="Moderate",25,IF('Market Input'!R15="High",35,40))))) | I40: =IF('Market Input'!G15="",0,IF('Market Input'!G15="Urban",40,IF('Market Input'!G15="College Town",38,IF('Market Input'!G15="Suburban",25,10)))) | J40: =IF('Market Input'!O15="",0,IF('Market Input'!O15="None",40,IF('Market Input'!O15="Weak",30,IF('Market Input'!O15="Moderate",15,5)))) | K40: =IF('Market Input'!P15="",0,IF('Market Input'!P15="None",5,IF('Market Input'!P15="Contact Only",15,IF('Market Input'!P15="Active Advocate",30,40)))) | L40: =IF('Market Input'!M15="",0,IF('Market Input'!M15<120,10,IF('Market Input'!M15<180,20,IF('Market Input'!M15<240,30,40)))) | M40: =IF('Market Input'!D15="","",ROUND((C40*0.20+D40*0.10+E40*0.10+F40*0.15+G40*0.10+H40*0.10+I40*0.10+J40*0.05+K40*0.05+L40*0.05)/40*100,0)) | N40: =IF(M40="","",IF(M40>=80,"A",IF(M40>=65,"B",IF(M40>=50,"C",IF(M40>=35,"D","F")))))
A41: ='Market Input'!A16 | B41: ='Market Input'!D16 | C41: =IF('Market Input'!E16="",0,IF('Market Input'!E16<25000,5,IF('Market Input'!E16<100000,10,IF('Market Input'!E16<250000,25,IF('Market Input'!E16<1000000,45,50))))) | D41: =IF('Market Input'!F16="",0,IF('Market Input'!F16<40000,15,IF('Market Input'!F16<60000,25,IF('Market Input'!F16<80000,35,40)))) | E41: =IF(OR('Market Input'!K16="",'Market Input'!E16="",'Market Input'!E16=0),0,LET(density,'Market Input'!K16/'Market Input'!E16*100000,IF(density<1,10,IF(density<5,25,IF(density<15,40,30))))) | F41: =IF('Market Input'!N16="",0,IF('Market Input'!N16=0,0,IF('Market Input'!N16<5000,10,IF('Market Input'!N16<15000,25,IF('Market Input'!N16<30000,35,40))))) | G41: =IF('Market Input'!Q16="",0,IF('Market Input'!Q16="Very Friendly",40,IF('Market Input'!Q16="Friendly",30,IF('Market Input'!Q16="Moderate",20,IF('Market Input'!Q16="Restrictive",10,0))))) | H41: =IF('Market Input'!R16="",0,IF('Market Input'!R16="None",0,IF('Market Input'!R16="Low",10,IF('Market Input'!R16="Moderate",25,IF('Market Input'!R16="High",35,40))))) | I41: =IF('Market Input'!G16="",0,IF('Market Input'!G16="Urban",40,IF('Market Input'!G16="College Town",38,IF('Market Input'!G16="Suburban",25,10)))) | J41: =IF('Market Input'!O16="",0,IF('Market Input'!O16="None",40,IF('Market Input'!O16="Weak",30,IF('Market Input'!O16="Moderate",15,5)))) | K41: =IF('Market Input'!P16="",0,IF('Market Input'!P16="None",5,IF('Market Input'!P16="Contact Only",15,IF('Market Input'!P16="Active Advocate",30,40)))) | L41: =IF('Market Input'!M16="",0,IF('Market Input'!M16<120,10,IF('Market Input'!M16<180,20,IF('Market Input'!M16<240,30,40)))) | M41: =IF('Market Input'!D16="","",ROUND((C41*0.20+D41*0.10+E41*0.10+F41*0.15+G41*0.10+H41*0.10+I41*0.10+J41*0.05+K41*0.05+L41*0.05)/40*100,0)) | N41: =IF(M41="","",IF(M41>=80,"A",IF(M41>=65,"B",IF(M41>=50,"C",IF(M41>=35,"D","F")))))
... A49: ='Market Input'!A24 | B49: ='Market Input'!D24 | C49: =IF('Market Input'!E24="",0,IF('Market Input'!E24<25000,5,IF('Market Input'!E24<100000,10,IF('Market Input'!E24<250000,25,IF('Market Input'!E24<1000000,45,50))))) | D49: =IF('Market Input'!F24="",0,IF('Market Input'!F24<40000,15,IF('Market Input'!F24<60000,25,IF('Market Input'!F24<80000,35,40)))) | E49: =IF(OR('Market Input'!K24="",'Market Input'!E24="",'Market Input'!E24=0),0,LET(density,'Market Input'!K24/'Market Input'!E24*100000,IF(density<1,10,IF(density<5,25,IF(density<15,40,30))))) | F49: =IF('Market Input'!N24="",0,IF('Market Input'!N24=0,0,IF('Market Input'!N24<5000,10,IF('Market Input'!N24<15000,25,IF('Market Input'!N24<30000,35,40))))) | G49: =IF('Market Input'!Q24="",0,IF('Market Input'!Q24="Very Friendly",40,IF('Market Input'!Q24="Friendly",30,IF('Market Input'!Q24="Moderate",20,IF('Market Input'!Q24="Restrictive",10,0))))) | H49: =IF('Market Input'!R24="",0,IF('Market Input'!R24="None",0,IF('Market Input'!R24="Low",10,IF('Market Input'!R24="Moderate",25,IF('Market Input'!R24="High",35,40))))) | I49: =IF('Market Input'!G24="",0,IF('Market Input'!G24="Urban",40,IF('Market Input'!G24="College Town",38,IF('Market Input'!G24="Suburban",25,10)))) | J49: =IF('Market Input'!O24="",0,IF('Market Input'!O24="None",40,IF('Market Input'!O24="Weak",30,IF('Market Input'!O24="Moderate",15,5)))) | K49: =IF('Market Input'!P24="",0,IF('Market Input'!P24="None",5,IF('Market Input'!P24="Contact Only",15,IF('Market Input'!P24="Active Advocate",30,40)))) | L49: =IF('Market Input'!M24="",0,IF('Market Input'!M24<120,10,IF('Market Input'!M24<180,20,IF('Market Input'!M24<240,30,40)))) | M49: =IF('Market Input'!D24="","",ROUND((C49*0.20+D49*0.10+E49*0.10+F49*0.15+G49*0.10+H49*0.10+I49*0.10+J49*0.05+K49*0.05+L49*0.05)/40*100,0)) | N49: =IF(M49="","",IF(M49>=80,"A",IF(M49>=65,"B",IF(M49>=50,"C",IF(M49>=35,"D","F")))))

Sheet Revenue Projections
A1: VENDOR COUNT & REVENUE PROJECTIONS
A3: ADJUSTABLE ASSUMPTIONS
B4: Assumption | C4: FM Value | D4: FT Value | E4: Source / Notes
A5: 1 | B5: Platform Adoption Rate (Year 1) | C5: 5% | D5: 3% | E5: Conservative — scales to 15-25% by Year 3
A6: 2 | B6: Avg Transaction $ (High Vol) | C6: $35.00 | D6: $14.00 | E6: Penn State Extension 2024 / FoodTruckProfit 2026
A7: 3 | B7: Avg Transaction $ (Mod Vol) | C7: $30.00 | D7: $13.00 | E7: Adjusted by volume tier
A8: 4 | B8: Avg Transaction $ (Low Vol) | C8: $25.00 | D8: $11.00 | E8: Adjusted by volume tier
A9: 5 | B9: Transactions/Week (High Vol) | C9: 25 | D9: 40 | E9: Platform transactions, not total vendor sales
A10: 6 | B10: Transactions/Week (Mod Vol) | C10: 12 | D10: 20
A11: 7 | B11: Transactions/Week (Low Vol) | C11: 5 | D11: 8
A12: 8 | B12: Vendor Tier Split: High % | C12: 15% | D12: 20%
A13: 9 | B13: Vendor Tier Split: Moderate % | C13: 50% | D13: 45%
A14: 10 | B14: Vendor Tier Split: Low % | C14: 35% | D14: 35%
A15: 11 | B15: Platform Fee (Buyer) | C15: 6.5% | D15: 6.5% | E15: From pricing.ts
A16: 11b | B16: Platform Fee (Vendor - Stripe) | C16: 6.5% | D16: 6.5% | E16: From pricing.ts — charged on platform transactions
A17: 11c | B17: Platform Fee (Vendor - External) | C17: 3.5% | D17: 3.5% | E17: From pricing.ts — charged on cash/Venmo/etc
A18: 11d | B18: Est. % Platform vs External | C18: 70% | D18: 85% | E18: Estimated split — platform transactions tend higher for FT
A19: 12 | B19: FM Direct-to-Consumer Farm % | C19: 15% | D19: N/A | E19: USDA Census benchmark
A20: 13 | B20: FT per capita ratio | C20: N/A | D20: 1 per 5,000 | E20: National avg for estimating FT count
A21: 14 | B21: Subscription: Free tier % | C21: 40% | D21: 40% | E21: Year 1 tier distribution
A22: 15 | B22: Subscription: Basic/Standard % | C22: 35% | D22: 35%
A23: 16 | B23: Subscription: Premium/Pro % | C23: 20% | D23: 20%
A24: 17 | B24: Subscription: Featured/Boss % | C24: 5% | D24: 5%
A25: 18 | B25: Sub Price: Free | C25: $0 | D25: $0
A26: 19 | B26: Sub Price: Basic/Standard | C26: $10 | D26: $10
A27: 20 | B27: Sub Price: Premium/Pro | C27: $25 | D27: $25
A28: MARKET PROJECTIONS (Year 1) | B28: Sub Price: Featured/Boss | C28: $50 | D28: $50
A29: Market ID | B29: City/County | C29: FM Score | D29: FT Score | E29: Est. FM Vendors | F29: Est. FT Vendors | G29: Total Vendors | H29: FM Monthly Rev | I29: FT Monthly Rev | J29: Sub Monthly Rev | K29: Total Monthly Rev | L29: Annual Revenue
A30: ='Market Input'!A5 | B30: ='Market Input'!D5 | C30: ='Scoring Engine'!M5 | D30: ='Scoring Engine'!M30 | E30: =IF('Market Input'!D5="","",MAX(0,ROUND(IF('Market Input'!L5="",'Market Input'!E5/20000,'Market Input'!L5*0.15)*0.05*MAX(0.5,C30/50),0))) | F30: =IF('Market Input'!D5="","",MAX(0,ROUND(IF('Market Input'!K5="",'Market Input'!E5/5000,'Market Input'!K5)*0.03*MAX(0.5,D30/50),0))) | G30: =IF(E30="","",E30+F30) | H30: =IF(E30="","",ROUND(E30*(0.15*25*35+0.50*12*30+0.35*5*25)*(0.70*0.13+0.30*0.10)*4.33,2)) | I30: =IF(F30="","",ROUND(F30*(0.20*40*14+0.45*20*13+0.35*8*11)*(0.85*0.13+0.15*0.10)*4.33,2)) | J30: =IF(G30="","",ROUND(G30*(0.40*0+0.35*10+0.20*25+0.05*50),2)) | K30: =IF(G30="","",H30+I30+J30) | L30: =IF(G30="","",(H30*0.65+I30*0.85+J30)*12)
A31: ='Market Input'!A6 | B31: ='Market Input'!D6 | C31: ='Scoring Engine'!M6 | D31: ='Scoring Engine'!M31 | E31: =IF('Market Input'!D6="","",MAX(0,ROUND(IF('Market Input'!L6="",'Market Input'!E6/20000,'Market Input'!L6*0.15)*0.05*MAX(0.5,C31/50),0))) | F31: =IF('Market Input'!D6="","",MAX(0,ROUND(IF('Market Input'!K6="",'Market Input'!E6/5000,'Market Input'!K6)*0.03*MAX(0.5,D31/50),0))) | G31: =IF(E31="","",E31+F31) | H31: =IF(E31="","",ROUND(E31*(0.15*25*35+0.50*12*30+0.35*5*25)*(0.70*0.13+0.30*0.10)*4.33,2)) | I31: =IF(F31="","",ROUND(F31*(0.20*40*14+0.45*20*13+0.35*8*11)*(0.85*0.13+0.15*0.10)*4.33,2)) | J31: =IF(G31="","",ROUND(G31*(0.40*0+0.35*10+0.20*25+0.05*50),2)) | K31: =IF(G31="","",H31+I31+J31) | L31: =IF(G31="","",(H31*0.65+I31*0.85+J31)*12)
A32: ='Market Input'!A7 | B32: ='Market Input'!D7 | C32: ='Scoring Engine'!M7 | D32: ='Scoring Engine'!M32 | E32: =IF('Market Input'!D7="","",MAX(0,ROUND(IF('Market Input'!L7="",'Market Input'!E7/20000,'Market Input'!L7*0.15)*0.05*MAX(0.5,C32/50),0))) | F32: =IF('Market Input'!D7="","",MAX(0,ROUND(IF('Market Input'!K7="",'Market Input'!E7/5000,'Market Input'!K7)*0.03*MAX(0.5,D32/50),0))) | G32: =IF(E32="","",E32+F32) | H32: =IF(E32="","",ROUND(E32*(0.15*25*35+0.50*12*30+0.35*5*25)*(0.70*0.13+0.30*0.10)*4.33,2)) | I32: =IF(F32="","",ROUND(F32*(0.20*40*14+0.45*20*13+0.35*8*11)*(0.85*0.13+0.15*0.10)*4.33,2)) | J32: =IF(G32="","",ROUND(G32*(0.40*0+0.35*10+0.20*25+0.05*50),2)) | K32: =IF(G32="","",H32+I32+J32) | L32: =IF(G32="","",(H32*0.65+I32*0.85+J32)*12)
A33: ='Market Input'!A8 | B33: ='Market Input'!D8 | C33: ='Scoring Engine'!M8 | D33: ='Scoring Engine'!M33 | E33: =IF('Market Input'!D8="","",MAX(0,ROUND(IF('Market Input'!L8="",'Market Input'!E8/20000,'Market Input'!L8*0.15)*0.05*MAX(0.5,C33/50),0))) | F33: =IF('Market Input'!D8="","",MAX(0,ROUND(IF('Market Input'!K8="",'Market Input'!E8/5000,'Market Input'!K8)*0.03*MAX(0.5,D33/50),0))) | G33: =IF(E33="","",E33+F33) | H33: =IF(E33="","",ROUND(E33*(0.15*25*35+0.50*12*30+0.35*5*25)*(0.70*0.13+0.30*0.10)*4.33,2)) | I33: =IF(F33="","",ROUND(F33*(0.20*40*14+0.45*20*13+0.35*8*11)*(0.85*0.13+0.15*0.10)*4.33,2)) | J33: =IF(G33="","",ROUND(G33*(0.40*0+0.35*10+0.20*25+0.05*50),2)) | K33: =IF(G33="","",H33+I33+J33) | L33: =IF(G33="","",(H33*0.65+I33*0.85+J33)*12)
A34: ='Market Input'!A9 | B34: ='Market Input'!D9 | C34: ='Scoring Engine'!M9 | D34: ='Scoring Engine'!M34 | E34: =IF('Market Input'!D9="","",MAX(0,ROUND(IF('Market Input'!L9="",'Market Input'!E9/20000,'Market Input'!L9*0.15)*0.05*MAX(0.5,C34/50),0))) | F34: =IF('Market Input'!D9="","",MAX(0,ROUND(IF('Market Input'!K9="",'Market Input'!E9/5000,'Market Input'!K9)*0.03*MAX(0.5,D34/50),0))) | G34: =IF(E34="","",E34+F34) | H34: =IF(E34="","",ROUND(E34*(0.15*25*35+0.50*12*30+0.35*5*25)*(0.70*0.13+0.30*0.10)*4.33,2)) | I34: =IF(F34="","",ROUND(F34*(0.20*40*14+0.45*20*13+0.35*8*11)*(0.85*0.13+0.15*0.10)*4.33,2)) | J34: =IF(G34="","",ROUND(G34*(0.40*0+0.35*10+0.20*25+0.05*50),2)) | K34: =IF(G34="","",H34+I34+J34) | L34: =IF(G34="","",(H34*0.65+I34*0.85+J34)*12)
A35: ='Market Input'!A10 | B35: ='Market Input'!D10 | C35: ='Scoring Engine'!M10 | D35: ='Scoring Engine'!M35 | E35: =IF('Market Input'!D10="","",MAX(0,ROUND(IF('Market Input'!L10="",'Market Input'!E10/20000,'Market Input'!L10*0.15)*0.05*MAX(0.5,C35/50),0))) | F35: =IF('Market Input'!D10="","",MAX(0,ROUND(IF('Market Input'!K10="",'Market Input'!E10/5000,'Market Input'!K10)*0.03*MAX(0.5,D35/50),0))) | G35: =IF(E35="","",E35+F35) | H35: =IF(E35="","",ROUND(E35*(0.15*25*35+0.50*12*30+0.35*5*25)*(0.70*0.13+0.30*0.10)*4.33,2)) | I35: =IF(F35="","",ROUND(F35*(0.20*40*14+0.45*20*13+0.35*8*11)*(0.85*0.13+0.15*0.10)*4.33,2)) | J35: =IF(G35="","",ROUND(G35*(0.40*0+0.35*10+0.20*25+0.05*50),2)) | K35: =IF(G35="","",H35+I35+J35) | L35: =IF(G35="","",(H35*0.65+I35*0.85+J35)*12)
A36: ='Market Input'!A11 | B36: ='Market Input'!D11 | C36: ='Scoring Engine'!M11 | D36: ='Scoring Engine'!M36 | E36: =IF('Market Input'!D11="","",MAX(0,ROUND(IF('Market Input'!L11="",'Market Input'!E11/20000,'Market Input'!L11*0.15)*0.05*MAX(0.5,C36/50),0))) | F36: =IF('Market Input'!D11="","",MAX(0,ROUND(IF('Market Input'!K11="",'Market Input'!E11/5000,'Market Input'!K11)*0.03*MAX(0.5,D36/50),0))) | G36: =IF(E36="","",E36+F36) | H36: =IF(E36="","",ROUND(E36*(0.15*25*35+0.50*12*30+0.35*5*25)*(0.70*0.13+0.30*0.10)*4.33,2)) | I36: =IF(F36="","",ROUND(F36*(0.20*40*14+0.45*20*13+0.35*8*11)*(0.85*0.13+0.15*0.10)*4.33,2)) | J36: =IF(G36="","",ROUND(G36*(0.40*0+0.35*10+0.20*25+0.05*50),2)) | K36: =IF(G36="","",H36+I36+J36) | L36: =IF(G36="","",(H36*0.65+I36*0.85+J36)*12)
